2021-01-27 11:28:01,827 : ERROR : COINBASE-f8b8d3: encountered an exception, reconnecting
Traceback (most recent call last):
  File "/usr/local/lib/python3.7/site-packages/cryptofeed/feedhandler.py", line 230, in _connect
    await self._handler(connection, handler)
  File "/usr/local/lib/python3.7/site-packages/cryptofeed/feedhandler.py", line 259, in _handler
    await handler(message, connection, self.last_msg[connection.uuid])
  File "/usr/local/lib/python3.7/site-packages/cryptofeed/exchange/coinbase.py", line 327, in message_handler
    await self._book_update(msg, timestamp)
  File "/usr/local/lib/python3.7/site-packages/cryptofeed/exchange/coinbase.py", line 136, in _book_update
    order_type=order_type
  File "/usr/local/lib/python3.7/site-packages/cryptofeed/feed.py", line 204, in callback
    await cb(**kwargs)
  File "/usr/local/lib/python3.7/site-packages/cryptofeed/callback.py", line 44, in __call__
    await super().__call__(feed, pair, order_id, timestamp, side, amount, price, receipt_timestamp, **kwargs)
  File "/usr/local/lib/python3.7/site-packages/cryptofeed/callback.py", line 21, in __call__
    await self.callback(*args, **kwargs)
TypeError: trade() takes 7 positional arguments but 8 were given
2021-01-27 11:28:04,177 : ERROR : COINBASE-f8b8d3: encountered an exception, reconnecting
Traceback (most recent call last):
  File "/usr/local/lib/python3.7/site-packages/cryptofeed/feedhandler.py", line 230, in _connect
    await self._handler(connection, handler)
  File "/usr/local/lib/python3.7/site-packages/cryptofeed/feedhandler.py", line 259, in _handler
    await handler(message, connection, self.last_msg[connection.uuid])
  File "/usr/local/lib/python3.7/site-packages/cryptofeed/exchange/coinbase.py", line 327, in message_handler
    await self._book_update(msg, timestamp)
  File "/usr/local/lib/python3.7/site-packages/cryptofeed/exchange/coinbase.py", line 136, in _book_update
    order_type=order_type
  File "/usr/local/lib/python3.7/site-packages/cryptofeed/feed.py", line 204, in callback
    await cb(**kwargs)
  File "/usr/local/lib/python3.7/site-packages/cryptofeed/callback.py", line 44, in __call__
    await super().__call__(feed, pair, order_id, timestamp, side, amount, price, receipt_timestamp, **kwargs)
  File "/usr/local/lib/python3.7/site-packages/cryptofeed/callback.py", line 21, in __call__
    await self.callback(*args, **kwargs)
TypeError: trade() takes 7 positional arguments but 8 were given
2021-01-27 11:28:06,478 : ERROR : COINBASE-f8b8d3: encountered an exception, reconnecting
Traceback (most recent call last):
  File "/usr/local/lib/python3.7/site-packages/cryptofeed/feedhandler.py", line 230, in _connect
    await self._handler(connection, handler)
  File "/usr/local/lib/python3.7/site-packages/cryptofeed/feedhandler.py", line 259, in _handler
    await handler(message, connection, self.last_msg[connection.uuid])
  File "/usr/local/lib/python3.7/site-packages/cryptofeed/exchange/coinbase.py", line 327, in message_handler
    await self._book_update(msg, timestamp)
  File "/usr/local/lib/python3.7/site-packages/cryptofeed/exchange/coinbase.py", line 136, in _book_update
    order_type=order_type
  File "/usr/local/lib/python3.7/site-packages/cryptofeed/feed.py", line 204, in callback
    await cb(**kwargs)
  File "/usr/local/lib/python3.7/site-packages/cryptofeed/callback.py", line 44, in __call__
    await super().__call__(feed, pair, order_id, timestamp, side, amount, price, receipt_timestamp, **kwargs)
  File "/usr/local/lib/python3.7/site-packages/cryptofeed/callback.py", line 21, in __call__
    await self.callback(*args, **kwargs)
TypeError: trade() takes 7 positional arguments but 8 were given
2021-01-27 11:28:08,772 : ERROR : COINBASE-f8b8d3: encountered an exception, reconnecting
Traceback (most recent call last):
  File "/usr/local/lib/python3.7/site-packages/cryptofeed/feedhandler.py", line 230, in _connect
    await self._handler(connection, handler)
  File "/usr/local/lib/python3.7/site-packages/cryptofeed/feedhandler.py", line 259, in _handler
    await handler(message, connection, self.last_msg[connection.uuid])
  File "/usr/local/lib/python3.7/site-packages/cryptofeed/exchange/coinbase.py", line 327, in message_handler
    await self._book_update(msg, timestamp)
  File "/usr/local/lib/python3.7/site-packages/cryptofeed/exchange/coinbase.py", line 136, in _book_update
    order_type=order_type
  File "/usr/local/lib/python3.7/site-packages/cryptofeed/feed.py", line 204, in callback
    await cb(**kwargs)
  File "/usr/local/lib/python3.7/site-packages/cryptofeed/callback.py", line 44, in __call__
    await super().__call__(feed, pair, order_id, timestamp, side, amount, price, receipt_timestamp, **kwargs)
  File "/usr/local/lib/python3.7/site-packages/cryptofeed/callback.py", line 21, in __call__
    await self.callback(*args, **kwargs)
TypeError: trade() takes 7 positional arguments but 8 were given
2021-01-27 11:28:10,939 : ERROR : COINBASE-f8b8d3: encountered an exception, reconnecting
Traceback (most recent call last):
  File "/usr/local/lib/python3.7/site-packages/cryptofeed/feedhandler.py", line 230, in _connect
    await self._handler(connection, handler)
  File "/usr/local/lib/python3.7/site-packages/cryptofeed/feedhandler.py", line 259, in _handler
    await handler(message, connection, self.last_msg[connection.uuid])
  File "/usr/local/lib/python3.7/site-packages/cryptofeed/exchange/coinbase.py", line 327, in message_handler
    await self._book_update(msg, timestamp)
  File "/usr/local/lib/python3.7/site-packages/cryptofeed/exchange/coinbase.py", line 136, in _book_update
    order_type=order_type
  File "/usr/local/lib/python3.7/site-packages/cryptofeed/feed.py", line 204, in callback
    await cb(**kwargs)
  File "/usr/local/lib/python3.7/site-packages/cryptofeed/callback.py", line 44, in __call__
    await super().__call__(feed, pair, order_id, timestamp, side, amount, price, receipt_timestamp, **kwargs)
  File "/usr/local/lib/python3.7/site-packages/cryptofeed/callback.py", line 21, in __call__
    await self.callback(*args, **kwargs)
TypeError: trade() takes 7 positional arguments but 8 were given
2021-01-27 11:56:08,086 : ERROR : COINBASE-862e10: encountered an exception, reconnecting
Traceback (most recent call last):
  File "/usr/local/lib/python3.7/site-packages/cryptofeed/feedhandler.py", line 230, in _connect
    await self._handler(connection, handler)
  File "/usr/local/lib/python3.7/site-packages/cryptofeed/feedhandler.py", line 259, in _handler
    await handler(message, connection, self.last_msg[connection.uuid])
  File "/usr/local/lib/python3.7/site-packages/cryptofeed/exchange/coinbase.py", line 327, in message_handler
    await self._book_update(msg, timestamp)
  File "/usr/local/lib/python3.7/site-packages/cryptofeed/exchange/coinbase.py", line 136, in _book_update
    order_type=order_type
  File "/usr/local/lib/python3.7/site-packages/cryptofeed/feed.py", line 204, in callback
    await cb(**kwargs)
  File "/usr/local/lib/python3.7/site-packages/cryptofeed/callback.py", line 44, in __call__
    await super().__call__(feed, pair, order_id, timestamp, side, amount, price, receipt_timestamp, **kwargs)
  File "/usr/local/lib/python3.7/site-packages/cryptofeed/callback.py", line 21, in __call__
    await self.callback(*args, **kwargs)
TypeError: trade() takes 7 positional arguments but 8 were given
2021-01-27 11:56:10,326 : ERROR : COINBASE-862e10: encountered an exception, reconnecting
Traceback (most recent call last):
  File "/usr/local/lib/python3.7/site-packages/cryptofeed/feedhandler.py", line 230, in _connect
    await self._handler(connection, handler)
  File "/usr/local/lib/python3.7/site-packages/cryptofeed/feedhandler.py", line 259, in _handler
    await handler(message, connection, self.last_msg[connection.uuid])
  File "/usr/local/lib/python3.7/site-packages/cryptofeed/exchange/coinbase.py", line 327, in message_handler
    await self._book_update(msg, timestamp)
  File "/usr/local/lib/python3.7/site-packages/cryptofeed/exchange/coinbase.py", line 136, in _book_update
    order_type=order_type
  File "/usr/local/lib/python3.7/site-packages/cryptofeed/feed.py", line 204, in callback
    await cb(**kwargs)
  File "/usr/local/lib/python3.7/site-packages/cryptofeed/callback.py", line 44, in __call__
    await super().__call__(feed, pair, order_id, timestamp, side, amount, price, receipt_timestamp, **kwargs)
  File "/usr/local/lib/python3.7/site-packages/cryptofeed/callback.py", line 21, in __call__
    await self.callback(*args, **kwargs)
TypeError: trade() takes 7 positional arguments but 8 were given
2021-01-27 11:56:12,585 : ERROR : COINBASE-862e10: encountered an exception, reconnecting
Traceback (most recent call last):
  File "/usr/local/lib/python3.7/site-packages/cryptofeed/feedhandler.py", line 230, in _connect
    await self._handler(connection, handler)
  File "/usr/local/lib/python3.7/site-packages/cryptofeed/feedhandler.py", line 259, in _handler
    await handler(message, connection, self.last_msg[connection.uuid])
  File "/usr/local/lib/python3.7/site-packages/cryptofeed/exchange/coinbase.py", line 327, in message_handler
    await self._book_update(msg, timestamp)
  File "/usr/local/lib/python3.7/site-packages/cryptofeed/exchange/coinbase.py", line 136, in _book_update
    order_type=order_type
  File "/usr/local/lib/python3.7/site-packages/cryptofeed/feed.py", line 204, in callback
    await cb(**kwargs)
  File "/usr/local/lib/python3.7/site-packages/cryptofeed/callback.py", line 44, in __call__
    await super().__call__(feed, pair, order_id, timestamp, side, amount, price, receipt_timestamp, **kwargs)
  File "/usr/local/lib/python3.7/site-packages/cryptofeed/callback.py", line 21, in __call__
    await self.callback(*args, **kwargs)
TypeError: trade() takes 7 positional arguments but 8 were given
2021-01-28 10:55:46,379 : ERROR : COINBASE-155573: encountered an exception, reconnecting
Traceback (most recent call last):
  File "/usr/local/lib/python3.7/site-packages/cryptofeed/feedhandler.py", line 230, in _connect
    await self._handler(connection, handler)
  File "/usr/local/lib/python3.7/site-packages/cryptofeed/feedhandler.py", line 259, in _handler
    await handler(message, connection, self.last_msg[connection.uuid])
  File "/usr/local/lib/python3.7/site-packages/cryptofeed/exchange/coinbase.py", line 327, in message_handler
    await self._book_update(msg, timestamp)
  File "/usr/local/lib/python3.7/site-packages/cryptofeed/exchange/coinbase.py", line 136, in _book_update
    order_type=order_type
  File "/usr/local/lib/python3.7/site-packages/cryptofeed/feed.py", line 204, in callback
    await cb(**kwargs)
  File "/usr/local/lib/python3.7/site-packages/cryptofeed/callback.py", line 44, in __call__
    await super().__call__(feed, pair, order_id, timestamp, side, amount, price, receipt_timestamp, **kwargs)
  File "/usr/local/lib/python3.7/site-packages/cryptofeed/callback.py", line 21, in __call__
    await self.callback(*args, **kwargs)
TypeError: test() takes 0 positional arguments but 8 were given
2021-01-28 10:55:55,120 : ERROR : COINBASE-155573: encountered an exception, reconnecting
Traceback (most recent call last):
  File "/usr/local/lib/python3.7/site-packages/cryptofeed/feedhandler.py", line 230, in _connect
    await self._handler(connection, handler)
  File "/usr/local/lib/python3.7/site-packages/cryptofeed/feedhandler.py", line 259, in _handler
    await handler(message, connection, self.last_msg[connection.uuid])
  File "/usr/local/lib/python3.7/site-packages/cryptofeed/exchange/coinbase.py", line 327, in message_handler
    await self._book_update(msg, timestamp)
  File "/usr/local/lib/python3.7/site-packages/cryptofeed/exchange/coinbase.py", line 136, in _book_update
    order_type=order_type
  File "/usr/local/lib/python3.7/site-packages/cryptofeed/feed.py", line 204, in callback
    await cb(**kwargs)
  File "/usr/local/lib/python3.7/site-packages/cryptofeed/callback.py", line 44, in __call__
    await super().__call__(feed, pair, order_id, timestamp, side, amount, price, receipt_timestamp, **kwargs)
  File "/usr/local/lib/python3.7/site-packages/cryptofeed/callback.py", line 21, in __call__
    await self.callback(*args, **kwargs)
TypeError: test() takes 0 positional arguments but 8 were given
2021-01-28 10:56:00,874 : ERROR : COINBASE-155573: encountered an exception, reconnecting
Traceback (most recent call last):
  File "/usr/local/lib/python3.7/site-packages/cryptofeed/feedhandler.py", line 230, in _connect
    await self._handler(connection, handler)
  File "/usr/local/lib/python3.7/site-packages/cryptofeed/feedhandler.py", line 259, in _handler
    await handler(message, connection, self.last_msg[connection.uuid])
  File "/usr/local/lib/python3.7/site-packages/cryptofeed/exchange/coinbase.py", line 327, in message_handler
    await self._book_update(msg, timestamp)
  File "/usr/local/lib/python3.7/site-packages/cryptofeed/exchange/coinbase.py", line 136, in _book_update
    order_type=order_type
  File "/usr/local/lib/python3.7/site-packages/cryptofeed/feed.py", line 204, in callback
    await cb(**kwargs)
  File "/usr/local/lib/python3.7/site-packages/cryptofeed/callback.py", line 44, in __call__
    await super().__call__(feed, pair, order_id, timestamp, side, amount, price, receipt_timestamp, **kwargs)
  File "/usr/local/lib/python3.7/site-packages/cryptofeed/callback.py", line 21, in __call__
    await self.callback(*args, **kwargs)
TypeError: test() takes 0 positional arguments but 8 were given
2021-01-28 11:39:15,890 : WARNING : COINBASE-d8b52f: received no messages within timeout, restarting connection
2021-01-28 11:39:45,926 : WARNING : COINBASE-d8b52f: encountered connection issue code = 1006 (connection closed abnormally [internal]), no reason - reconnecting...
Traceback (most recent call last):
  File "/usr/local/lib/python3.7/site-packages/websockets/protocol.py", line 827, in transfer_data
    message = await self.read_message()
  File "/usr/local/lib/python3.7/site-packages/websockets/protocol.py", line 895, in read_message
    frame = await self.read_data_frame(max_size=self.max_size)
  File "/usr/local/lib/python3.7/site-packages/websockets/protocol.py", line 971, in read_data_frame
    frame = await self.read_frame(max_size)
  File "/usr/local/lib/python3.7/site-packages/websockets/protocol.py", line 1051, in read_frame
    extensions=self.extensions,
  File "/usr/local/lib/python3.7/site-packages/websockets/framing.py", line 105, in read
    data = await reader(2)
  File "/usr/local/Cellar/python/3.7.2_2/Frameworks/Python.framework/Versions/3.7/lib/python3.7/asyncio/streams.py", line 679, in readexactly
    await self._wait_for_data('readexactly')
  File "/usr/local/Cellar/python/3.7.2_2/Frameworks/Python.framework/Versions/3.7/lib/python3.7/asyncio/streams.py", line 473, in _wait_for_data
    await self._waiter
concurrent.futures._base.CancelledError

The above exception was the direct cause of the following exception:

Traceback (most recent call last):
  File "/usr/local/lib/python3.7/site-packages/cryptofeed/feedhandler.py", line 230, in _connect
    await self._handler(connection, handler)
  File "/usr/local/lib/python3.7/site-packages/cryptofeed/feedhandler.py", line 257, in _handler
    async for message in connection.read():
  File "/usr/local/lib/python3.7/site-packages/cryptofeed/connection.py", line 56, in read
    async for data in self.conn:
  File "/usr/local/lib/python3.7/site-packages/websockets/protocol.py", line 439, in __aiter__
    yield await self.recv()
  File "/usr/local/lib/python3.7/site-packages/websockets/protocol.py", line 509, in recv
    await self.ensure_open()
  File "/usr/local/lib/python3.7/site-packages/websockets/protocol.py", line 812, in ensure_open
    raise self.connection_closed_exc()
websockets.exceptions.ConnectionClosedError: code = 1006 (connection closed abnormally [internal]), no reason
2021-01-28 11:42:19,040 : WARNING : COINBASE-d8b52f: encountered connection issue Multiple exceptions: [Errno 60] Connect call failed ('104.18.14.237', 443), [Errno 60] Connect call failed ('104.18.15.237', 443), [Errno 65] No route to host, [Errno 65] No route to host - reconnecting...
Traceback (most recent call last):
  File "/usr/local/lib/python3.7/site-packages/cryptofeed/feedhandler.py", line 224, in _connect
    async with conn.connect() as connection:
  File "/usr/local/Cellar/python/3.7.2_2/Frameworks/Python.framework/Versions/3.7/lib/python3.7/contextlib.py", line 170, in __aenter__
    return await self.gen.__anext__()
  File "/usr/local/lib/python3.7/site-packages/cryptofeed/connection.py", line 36, in connect
    self.conn = await websockets.connect(self.address, **self.kwargs)
  File "/usr/local/lib/python3.7/site-packages/websockets/client.py", line 535, in __await_impl__
    transport, protocol = await self._create_connection()
  File "/usr/local/Cellar/python/3.7.2_2/Frameworks/Python.framework/Versions/3.7/lib/python3.7/asyncio/base_events.py", line 968, in create_connection
    ', '.join(str(exc) for exc in exceptions)))
OSError: Multiple exceptions: [Errno 60] Connect call failed ('104.18.14.237', 443), [Errno 60] Connect call failed ('104.18.15.237', 443), [Errno 65] No route to host, [Errno 65] No route to host
2021-01-28 11:44:52,835 : WARNING : COINBASE-d8b52f: encountered connection issue Multiple exceptions: [Errno 60] Connect call failed ('104.18.14.237', 443), [Errno 60] Connect call failed ('104.18.15.237', 443), [Errno 65] No route to host, [Errno 65] No route to host - reconnecting...
Traceback (most recent call last):
  File "/usr/local/lib/python3.7/site-packages/cryptofeed/feedhandler.py", line 224, in _connect
    async with conn.connect() as connection:
  File "/usr/local/Cellar/python/3.7.2_2/Frameworks/Python.framework/Versions/3.7/lib/python3.7/contextlib.py", line 170, in __aenter__
    return await self.gen.__anext__()
  File "/usr/local/lib/python3.7/site-packages/cryptofeed/connection.py", line 36, in connect
    self.conn = await websockets.connect(self.address, **self.kwargs)
  File "/usr/local/lib/python3.7/site-packages/websockets/client.py", line 535, in __await_impl__
    transport, protocol = await self._create_connection()
  File "/usr/local/Cellar/python/3.7.2_2/Frameworks/Python.framework/Versions/3.7/lib/python3.7/asyncio/base_events.py", line 968, in create_connection
    ', '.join(str(exc) for exc in exceptions)))
OSError: Multiple exceptions: [Errno 60] Connect call failed ('104.18.14.237', 443), [Errno 60] Connect call failed ('104.18.15.237', 443), [Errno 65] No route to host, [Errno 65] No route to host
2021-01-28 11:47:27,931 : WARNING : COINBASE-d8b52f: encountered connection issue Multiple exceptions: [Errno 60] Connect call failed ('104.18.14.237', 443), [Errno 60] Connect call failed ('104.18.15.237', 443), [Errno 65] No route to host, [Errno 65] No route to host - reconnecting...
Traceback (most recent call last):
  File "/usr/local/lib/python3.7/site-packages/cryptofeed/feedhandler.py", line 224, in _connect
    async with conn.connect() as connection:
  File "/usr/local/Cellar/python/3.7.2_2/Frameworks/Python.framework/Versions/3.7/lib/python3.7/contextlib.py", line 170, in __aenter__
    return await self.gen.__anext__()
  File "/usr/local/lib/python3.7/site-packages/cryptofeed/connection.py", line 36, in connect
    self.conn = await websockets.connect(self.address, **self.kwargs)
  File "/usr/local/lib/python3.7/site-packages/websockets/client.py", line 535, in __await_impl__
    transport, protocol = await self._create_connection()
  File "/usr/local/Cellar/python/3.7.2_2/Frameworks/Python.framework/Versions/3.7/lib/python3.7/asyncio/base_events.py", line 968, in create_connection
    ', '.join(str(exc) for exc in exceptions)))
OSError: Multiple exceptions: [Errno 60] Connect call failed ('104.18.14.237', 443), [Errno 60] Connect call failed ('104.18.15.237', 443), [Errno 65] No route to host, [Errno 65] No route to host
2021-01-28 11:50:07,611 : WARNING : COINBASE-d8b52f: encountered connection issue Multiple exceptions: [Errno 60] Connect call failed ('104.18.14.237', 443), [Errno 60] Connect call failed ('104.18.15.237', 443), [Errno 65] No route to host, [Errno 65] No route to host - reconnecting...
Traceback (most recent call last):
  File "/usr/local/lib/python3.7/site-packages/cryptofeed/feedhandler.py", line 224, in _connect
    async with conn.connect() as connection:
  File "/usr/local/Cellar/python/3.7.2_2/Frameworks/Python.framework/Versions/3.7/lib/python3.7/contextlib.py", line 170, in __aenter__
    return await self.gen.__anext__()
  File "/usr/local/lib/python3.7/site-packages/cryptofeed/connection.py", line 36, in connect
    self.conn = await websockets.connect(self.address, **self.kwargs)
  File "/usr/local/lib/python3.7/site-packages/websockets/client.py", line 535, in __await_impl__
    transport, protocol = await self._create_connection()
  File "/usr/local/Cellar/python/3.7.2_2/Frameworks/Python.framework/Versions/3.7/lib/python3.7/asyncio/base_events.py", line 968, in create_connection
    ', '.join(str(exc) for exc in exceptions)))
OSError: Multiple exceptions: [Errno 60] Connect call failed ('104.18.14.237', 443), [Errno 60] Connect call failed ('104.18.15.237', 443), [Errno 65] No route to host, [Errno 65] No route to host
2021-01-28 11:52:55,564 : WARNING : COINBASE-d8b52f: encountered connection issue Multiple exceptions: [Errno 60] Connect call failed ('104.18.14.237', 443), [Errno 60] Connect call failed ('104.18.15.237', 443), [Errno 65] No route to host, [Errno 65] No route to host - reconnecting...
Traceback (most recent call last):
  File "/usr/local/lib/python3.7/site-packages/cryptofeed/feedhandler.py", line 224, in _connect
    async with conn.connect() as connection:
  File "/usr/local/Cellar/python/3.7.2_2/Frameworks/Python.framework/Versions/3.7/lib/python3.7/contextlib.py", line 170, in __aenter__
    return await self.gen.__anext__()
  File "/usr/local/lib/python3.7/site-packages/cryptofeed/connection.py", line 36, in connect
    self.conn = await websockets.connect(self.address, **self.kwargs)
  File "/usr/local/lib/python3.7/site-packages/websockets/client.py", line 535, in __await_impl__
    transport, protocol = await self._create_connection()
  File "/usr/local/Cellar/python/3.7.2_2/Frameworks/Python.framework/Versions/3.7/lib/python3.7/asyncio/base_events.py", line 968, in create_connection
    ', '.join(str(exc) for exc in exceptions)))
OSError: Multiple exceptions: [Errno 60] Connect call failed ('104.18.14.237', 443), [Errno 60] Connect call failed ('104.18.15.237', 443), [Errno 65] No route to host, [Errno 65] No route to host
